<?xml version="1.0"?>
<robot name="scara_robot" xmlns:xacro="http://www.ros.org/wiki/xacro">

  <!-- Link base -->
  <link name="base_link">
    <visual>
        <geometry>
        <cylinder radius="0.1" length="0.9"/>
        </geometry>
        <!-- La mitad de la altura hacia abajo para que apoye sobre el piso -->
        <origin xyz="0 0 0.45" rpy="0 0 0"/>
        <material name="gray">
        <color rgba="0.4 0.4 0.4 1.0"/>
        </material>
    </visual>
  </link>

  <!-- Primer eslabón -->
  <joint name="joint1" type="revolute">
    <origin xyz="0 0 0.9" rpy="0 0 0"/>
    <axis xyz="0 0 1"/>
    <parent link="base_link"/>
    <child link="link1"/>
    <limit lower="-3.14" upper="3.14" effort="1.0" velocity="1.0"/>
  </joint>
  <link name="link1">
    <visual>
      <geometry><box size="0.6 0.05 0.05"/></geometry>
      <origin xyz="0.3 0 0" rpy="0 0 0"/>
    </visual>
  </link>

  <!-- Segundo eslabón -->
  <joint name="joint2" type="revolute">
    <origin xyz="0.6 0 0" rpy="0 0 0"/>
    <axis xyz="0 0 1"/>
    <parent link="link1"/>
    <child link="link2"/>
    <limit lower="-3.14" upper="3.14" effort="1.0" velocity="1.0"/>
  </joint>
  <link name="link2">
    <visual>
      <geometry><box size="0.3 0.05 0.05"/></geometry>
      <origin xyz="0.2 0 0" rpy="0 0 0"/>
    </visual>
  </link>

  <!-- Movimiento vertical (prismático) -->
  <joint name="joint3" type="prismatic">
    <origin xyz="0.4 0 0" rpy="0 0 0"/>
    <axis xyz="0 0 -1"/>
    <parent link="link2"/>
    <child link="tool"/>
    <limit lower="0.0" upper="0.9" effort="10" velocity="0.5"/>
  </joint>
  <link name="tool">
    <visual>
      <geometry><cylinder radius="0.03" length="0.9"/></geometry>
      <origin xyz="0 0 0.45" rpy="0 0 0"/>
    </visual>
  </link>

</robot>
