<?xml version="1.0"?>
<robot name="robot_trr" xmlns:xacro="http://www.ros.org/wiki/xacro">

  <!-- Link base -->
  <link name="base_link">
    <visual>
      <geometry>
        <box size="0.2 0.2 0.05"/>
      </geometry>
      <material name="blue">
        <color rgba="0 0 1 1"/>
      </material>
    </visual>
  </link>

  <!-- Primer eje: traslacional -->
  <joint name="joint1" type="prismatic">
    <parent link="base_link"/>
    <child link="link1"/>
    <axis xyz="0 0 1"/>
    <limit lower="0" upper="0.5" effort="10" velocity="0.5"/>
  </joint>

  <link name="link1">
    <visual>
      <geometry>
        <cylinder radius="0.05" length="0.2"/>
      </geometry>
      <material name="red">
        <color rgba="1 0 0 1"/>
      </material>
    </visual>
  </link>

  <!-- Segundo eje: rotacional -->
  <joint name="joint2" type="revolute">
    <parent link="link1"/>
    <child link="link2"/>
    <axis xyz="0 1 0"/>
    <limit lower="-1.57" upper="1.57" effort="5" velocity="1.0"/>
  </joint>

  <link name="link2">
    <visual>
      <geometry>
        <cylinder radius="0.04" length="0.3"/>
      </geometry>
      <material name="green">
        <color rgba="0 1 0 1"/>
      </material>
    </visual>
  </link>

  <!-- Tercer eje: rotacional -->
  <joint name="joint3" type="revolute">
    <parent link="link2"/>
    <child link="link3"/>
    <axis xyz="0 0 1"/>
    <limit lower="-3.14" upper="3.14" effort="5" velocity="1.0"/>
  </joint>

  <link name="link3">
    <visual>
      <geometry>
        <cylinder radius="0.03" length="0.2"/>
      </geometry>
      <material name="yellow">
        <color rgba="1 1 0 1"/>
      </material>
    </visual>
  </link>

</robot>

